Workbook

Sheet xlookup
A1: Table 1
A2: Employee ID | B2: Name | C2: Designation | D2: Salary (₹) | E2: Experience
A3: E101 | B3: Arjun Sharma | C3: Manager | D3: 120000 | E3: 15
A4: E102 | B4: Priya Mukherjee | C4: Assistant Manager | D4: 100000 | E4: 2
A5: E103 | B5: Rohit Patel | C5: Engineer | D5: 90000 | E5: 4
A6: E104 | B6: Aisha Verma | C6: Analyst | D6: 80000 | E6: 3
A7: E105 | B7: Suresh Kumar | C7: Technician | D7: 70000 | E7: 0
A8: E106 | B8: Deepa Nair | C8: Sales Representative | D8: 76000 | E8: 2
A9: E107 | B9: Vikram Singh | C9: Designer | D9: 84000 | E9: 6
A10: E108 | B10: Lakshmi Raghavan | C10: HR Specialist | D10: 96000 | E10: 6
A11: E109 | B11: Ramesh Joshi | C11: Accountant | D11: 92000 | E11: 8
A12: E110 | B12: Anjali Deshpande | C12: Software Developer | D12: 110000 | E12: 9
A15: Example 1 | G15: Example 2
A16: Employee ID | B16: Salary (₹) | G16: Name | H16: Employee ID
A17: E101 | B17: =XLOOKUP(A17,$A$3:$A$12,$D$3:$D$12) -> #NAME? | G17: Arjun Sharma | H17: =XLOOKUP(G17,$B$3:$B$12,$A$3:$A$12) -> #NAME?
A18: E102 | B18: =XLOOKUP(A18,$A$3:$A$12,$D$3:$D$12) -> #NAME? | G18: Priya Mukherjee | H18: =XLOOKUP(G18,$B$3:$B$12,$A$3:$A$12) -> #NAME?
A19: E103 | B19: =XLOOKUP(A19,$A$3:$A$12,$D$3:$D$12) -> #NAME? | G19: Rohit Patel | H19: =XLOOKUP(G19,$B$3:$B$12,$A$3:$A$12) -> #NAME?
A20: E104 | B20: =XLOOKUP(A20,$A$3:$A$12,$D$3:$D$12) -> #NAME? | G20: Aisha Verma | H20: =XLOOKUP(G20,$B$3:$B$12,$A$3:$A$12) -> #NAME?
A21: E105 | B21: =XLOOKUP(A21,$A$3:$A$12,$D$3:$D$12) -> #NAME? | G21: Suresh Kumar | H21: =XLOOKUP(G21,$B$3:$B$12,$A$3:$A$12) -> #NAME?
A22: E106 | B22: =XLOOKUP(A22,$A$3:$A$12,$D$3:$D$12) -> #NAME? | G22: Deepa Nair | H22: =XLOOKUP(G22,$B$3:$B$12,$A$3:$A$12) -> #NAME?
A23: E107 | B23: =XLOOKUP(A23,$A$3:$A$12,$D$3:$D$12) -> #NAME? | G23: Vikram Singh | H23: =XLOOKUP(G23,$B$3:$B$12,$A$3:$A$12) -> #NAME?
A24: E108 | B24: =XLOOKUP(A24,$A$3:$A$12,$D$3:$D$12) -> #NAME? | G24: Lakshmi Raghavan | H24: =XLOOKUP(G24,$B$3:$B$12,$A$3:$A$12) -> #NAME?
A25: E109 | B25: =XLOOKUP(A25,$A$3:$A$12,$D$3:$D$12) -> #NAME? | G25: Ramesh Joshi | H25: =XLOOKUP(G25,$B$3:$B$12,$A$3:$A$12) -> #NAME?
A26: E110 | B26: =XLOOKUP(A26,$A$3:$A$12,$D$3:$D$12) -> #NAME? | G26: Anjali Deshpande | H26: =XLOOKUP(G26,$B$3:$B$12,$A$3:$A$12) -> #NAME?
A30: Table 2
A31: Employee ID | B31: E101 | C31: E102 | D31: E103 | E31: E104 | F31: E105 | G31: E106 | H31: E107 | I31: E108 | J31: E109 | K31: E110
A32: Name | B32: Arjun Sharma | C32: Priya Mukherjee | D32: Rohit Patel | E32: Aisha Verma | F32: Suresh Kumar | G32: Deepa Nair | H32: Vikram Singh | I32: Lakshmi Raghavan | J32: Ramesh Joshi | K32: Anjali Deshpande
A33: Designation | B33: Manager | C33: Assistant Manager | D33: Engineer | E33: Analyst | F33: Technician | G33: Sales Representative | H33: Designer | I33: HR Specialist | J33: Accountant | K33: Software Developer
A34: Salary (₹) | B34: 120000 | C34: 100000 | D34: 90000 | E34: 80000 | F34: 70000 | G34: 76000 | H34: 84000 | I34: 96000 | J34: 92000 | K34: 110000
A35: Experience | B35: 15 | C35: 2 | D35: 4 | E35: 3 | F35: 0 | G35: 2 | H35: 6 | I35: 6 | J35: 8 | K35: 9
A38: Employee ID | B38: E101 | C38: E102 | D38: E103 | E38: E104 | F38: E105 | G38: E106 | H38: E107 | I38: E108 | J38: E109 | K38: E110
A39: Salary (₹) | B39: =XLOOKUP(B38,$B$31:$K$31,$B$34:$K$34) -> #NAME? | C39: =XLOOKUP(C38,$B$31:$K$31,$B$34:$K$34) -> #NAME? | D39: =XLOOKUP(D38,$B$31:$K$31,$B$34:$K$34) -> #NAME? | E39: =XLOOKUP(E38,$B$31:$K$31,$B$34:$K$34) -> #NAME? | F39: =XLOOKUP(F38,$B$31:$K$31,$B$34:$K$34) -> #NAME? | G39: =XLOOKUP(G38,$B$31:$K$31,$B$34:$K$34) -> #NAME? | H39: =XLOOKUP(H38,$B$31:$K$31,$B$34:$K$34) -> #NAME? | I39: =XLOOKUP(I38,$B$31:$K$31,$B$34:$K$34) -> #NAME? | ... K39: =XLOOKUP(K38,$B$31:$K$31,$B$34:$K$34) -> #NAME?
A42: Table 3
A43: Employee ID | B43: Name | C43: Designation | D43: Salary (₹) | E43: Experience | F43: Bonus | I43: Table 4
A44: E101 | B44: Arjun Sharma | C44: Manager | D44: 120000 | E44: 15 | F44: =VLOOKUP(A44,'vlookup Table 2'!$A$3:$B$12,2) -> 0.05 | I44: Experience | J44: Bonus
A45: E102 | B45: Priya Mukherjee | C45: Assistant Manager | D45: 100000 | E45: 2 | F45: =VLOOKUP(A45,'vlookup Table 2'!$A$3:$B$12,2) -> 0.03 | I45: 0 | J45: 2
A46: E103 | B46: Rohit Patel | C46: Engineer | D46: 90000 | E46: 4 | F46: =VLOOKUP(A46,'vlookup Table 2'!$A$3:$B$12,2) -> 0.04 | I46: 2 | J46: 4
A47: E104 | B47: Aisha Verma | C47: Analyst | D47: 80000 | E47: 3 | F47: =VLOOKUP(A47,'vlookup Table 2'!$A$3:$B$12,2) -> 0.035 | I47: 5 | J47: 12
A48: E105 | B48: Suresh Kumar | C48: Technician | D48: 70000 | E48: 0 | F48: =VLOOKUP(A48,'vlookup Table 2'!$A$3:$B$12,2) -> 0.04 | I48: 10 | J48: 15
A49: E106 | B49: Deepa Nair | C49: Sales Representative | D49: 76000 | E49: 2 | F49: =VLOOKUP(A49,'vlookup Table 2'!$A$3:$B$12,2) -> 0.035 | I49: 20 | J49: 16
...

Sheet Hllokup
A2: Table 1
A3: Employee ID | B3: E101 | C3: E102 | D3: E103 | E3: E104 | F3: E105 | G3: E106 | H3: E107 | I3: E108 | J3: E109 | K3: E110
A4: Name | B4: Arjun Sharma | C4: Priya Mukherjee | D4: Rohit Patel | E4: Aisha Verma | F4: Suresh Kumar | G4: Deepa Nair | H4: Vikram Singh | I4: Lakshmi Raghavan | J4: Ramesh Joshi | K4: Anjali Deshpande
A5: Designation | B5: Manager | C5: Assistant Manager | D5: Engineer | E5: Analyst | F5: Technician | G5: Sales Representative | H5: Designer | I5: HR Specialist | J5: Accountant | K5: Software Developer
A6: Salary (₹) | B6: 1,20,000 | C6: 1,00,000 | D6: 90000 | E6: 80000 | F6: 70000 | G6: 76000 | H6: 84000 | I6: 96000 | J6: 92000 | K6: 1,10,000
A7: Experience | B7: 15 | C7: 2 | D7: 4 | E7: 3 | F7: 0 | G7: 2 | H7: 6 | I7: 6 | J7: 8 | K7: 9
A10: Example 1
A11: Employee ID | B11: E101 | C11: E102 | D11: E103 | E11: E104 | F11: E105 | G11: E106 | H11: E107 | I11: E108 | J11: E109 | K11: E110
A12: Salary (₹) | B12: 1,20,000.00 | C12: 1,00,000.00 | D12: 90000 | E12: 80000 | F12: 70000 | G12: 76000 | H12: 84000 | I12: 96000 | J12: 92000 | K12: 1,10,000.00
A13: Designation | B13: =HLOOKUP(B11,$B$3:$K$7,3) -> Manager | C13: =HLOOKUP(C11,$B$3:$K$7,3) -> Assistant Manager | D13: =HLOOKUP(D11,$B$3:$K$7,3) -> Engineer | E13: =HLOOKUP(E11,$B$3:$K$7,3) -> Analyst | F13: =HLOOKUP(F11,$B$3:$K$7,3) -> Technician | G13: =HLOOKUP(G11,$B$3:$K$7,3) -> Sales Representative | H13: =HLOOKUP(H11,$B$3:$K$7,3) -> Designer | I13: =HLOOKUP(I11,$B$3:$K$7,3) -> HR Specialist | ... K13: =HLOOKUP(K11,$B$3:$K$7,3) -> Software Developer

Sheet vlookup Table 2
A1: Table 2
A2: Employee ID | B2: Bonus (%)
A3: E101 | B3: 0.05
A4: E102 | B4: 0.03
A5: E103 | B5: 0.04
A6: E104 | B6: 0.035
A7: E105 | B7: 0.04
A8: E106 | B8: 0.035
A9: E107 | B9: 0.045
A10: E108 | B10: 0.03
A11: E109 | B11: 0.04
A12: E110 | B12: 0.05

Sheet vlookup dataset
A1: Table 1 | H1: Table 2 | K1: Table 3
A2: Employee ID | B2: Name | C2: Designation | D2: Salary (₹) | E2: Experience | H2: Employee ID | I2: Bonus (%) | K2: Experience | L2: Bonus
A3: E101 | B3: Arjun Sharma | C3: Manager | D3: 120000 | E3: 15 | H3: E101 | I3: 0.05 | K3: 0 | L3: 2
A4: E102 | B4: Priya Mukherjee | C4: Assistant Manager | D4: 100000 | E4: 2 | H4: E102 | I4: 0.03 | K4: 2 | L4: 4
A5: E103 | B5: Rohit Patel | C5: Engineer | D5: 90000 | E5: 4 | H5: E103 | I5: 0.04 | K5: 5 | L5: 12
A6: E104 | B6: Aisha Verma | C6: Analyst | D6: 80000 | E6: 3 | H6: E104 | I6: 0.035 | K6: 10 | L6: 15
A7: E105 | B7: Suresh Kumar | C7: Technician | D7: 70000 | E7: 0 | H7: E105 | I7: 0.04 | K7: 20 | L7: 16
A8: E106 | B8: Deepa Nair | C8: Sales Representative | D8: 76000 | E8: 2 | H8: E106 | I8: 0.035
A9: E107 | B9: Vikram Singh | C9: Designer | D9: 84000 | E9: 6 | H9: E107 | I9: 0.045
A10: E108 | B10: Lakshmi Raghavan | C10: HR Specialist | D10: 96000 | E10: 6 | H10: E108 | I10: 0.03
A11: E109 | B11: Ramesh Joshi | C11: Accountant | D11: 92000 | E11: 8 | H11: E109 | I11: 0.04
A12: E110 | B12: Anjali Deshpande | C12: Software Developer | D12: 110000 | E12: 9 | H12: E110 | I12: 0.05
A15: Example 1 | D15: Example 2
A16: Employee ID | B16: Salary | D16: Name | E16: salary
A17: E101 | B17: =VLOOKUP(A17,$A$3:$D$12,4) -> 120000 | D17: Arjun Sharma | E17: =VLOOKUP(D17,$B$3:$D$12,3) -> 120000
A18: E102 | B18: =VLOOKUP(A18,$A$3:$D$12,4) -> 100000 | D18: Priya Mukherjee | E18: =VLOOKUP(D18,$B$3:$D$12,3) -> 100000
A19: E103 | B19: =VLOOKUP(A19,$A$3:$D$12,4) -> 90000 | D19: Rohit Patel | E19: =VLOOKUP(D19,$B$3:$D$12,3) -> 90000
A20: E104 | B20: =VLOOKUP(A20,$A$3:$D$12,4) -> 80000 | D20: Aisha Verma | E20: =VLOOKUP(D20,$B$3:$D$12,3) -> #N/A
A21: E105 | B21: =VLOOKUP(A21,$A$3:$D$12,4) -> 70000 | D21: Suresh Kumar | E21: =VLOOKUP(D21,$B$3:$D$12,3) -> 70000
A22: E106 | B22: =VLOOKUP(A22,$A$3:$D$12,4) -> 76000 | D22: Deepa Nair | E22: =VLOOKUP(D22,$B$3:$D$12,3) -> 120000
A23: E107 | B23: =VLOOKUP(A23,$A$3:$D$12,4) -> 84000 | D23: Vikram Singh | E23: =VLOOKUP(D23,$B$3:$D$12,3) -> 110000
A24: E108 | B24: =VLOOKUP(A24,$A$3:$D$12,4) -> 96000 | D24: Lakshmi Raghavan | E24: =VLOOKUP(D24,$B$3:$D$12,3) -> 120000
A25: E109 | B25: =VLOOKUP(A25,$A$3:$D$12,4) -> 92000 | D25: Ramesh Joshi | E25: =VLOOKUP(D25,$B$3:$D$12,3) -> 100000
A26: E110 | B26: =VLOOKUP(A26,$A$3:$D$12,4) -> 110000 | D26: Anjali Deshpande | E26: =VLOOKUP(D26,$B$3:$D$12,3) -> #N/A
A28: Example 3
A29: Employee ID | B29: Name | C29: Designation | D29: Salary (₹) | E29: Experience | F29: Bonus (%) | G29: Bonus (%) | H29: Bonus (%) | I29: Bonus (%)
A30: E105 | B30: =VLOOKUP(A30,$A$3:$E$12,2,2) -> Suresh Kumar | C30: =VLOOKUP(A30,$A$3:$C$12,3) -> Technician | D30: =VLOOKUP(A30,$A$3:$D$12,4) -> 70000 | E30: =VLOOKUP(A30,$A$3:$E$12,5,1) -> 0 | F30: =VLOOKUP(A30,$H$3:$I$12,2) -> 0.04
A31: E106 | B31: =VLOOKUP(A31,$A$3:$E$12,2,2) -> Deepa Nair | C31: =VLOOKUP(A31,$A$3:$C$12,3) -> Sales Representative | D31: =VLOOKUP(A31,$A$3:$D$12,4) -> 76000 | E31: =VLOOKUP(A31,$A$3:$E$12,5,1) -> 2 | F31: =VLOOKUP(A31,$H$3:$I$12,2) -> 0.035
A32: E104 | B32: =VLOOKUP(A32,$A$3:$E$12,2,2) -> Aisha Verma | C32: =VLOOKUP(A32,$A$3:$C$12,3) -> Analyst | D32: =VLOOKUP(A32,$A$3:$D$12,4) -> 80000 | E32: =VLOOKUP(A32,$A$3:$E$12,5,1) -> 3 | F32: =VLOOKUP(A32,$H$3:$I$12,2) -> 0.035
A33: E107 | B33: =VLOOKUP(A33,$A$3:$E$12,2,2) -> Vikram Singh | C33: =VLOOKUP(A33,$A$3:$C$12,3) -> Designer | D33: =VLOOKUP(A33,$A$3:$D$12,4) -> 84000 | E33: =VLOOKUP(A33,$A$3:$E$12,5,1) -> 6 | F33: =VLOOKUP(A33,$H$3:$I$12,2) -> 0.045
A34: E103 | B34: =VLOOKUP(A34,$A$3:$E$12,2,2) -> Rohit Patel | C34: =VLOOKUP(A34,$A$3:$C$12,3) -> Engineer | D34: =VLOOKUP(A34,$A$3:$D$12,4) -> 90000 | E34: =VLOOKUP(A34,$A$3:$E$12,5,1) -> 4 | F34: =VLOOKUP(A34,$H$3:$I$12,2) -> 0.04
A35: E109 | B35: =VLOOKUP(A35,$A$3:$E$12,2,2) -> Ramesh Joshi | C35: =VLOOKUP(A35,$A$3:$C$12,3) -> Accountant | D35: =VLOOKUP(A35,$A$3:$D$12,4) -> 92000 | E35: =VLOOKUP(A35,$A$3:$E$12,5,1) -> 8 | F35: =VLOOKUP(A35,$H$3:$I$12,2) -> 0.04
A36: E108 | B36: =VLOOKUP(A36,$A$3:$E$12,2,2) -> Lakshmi Raghavan | C36: =VLOOKUP(A36,$A$3:$C$12,3) -> HR Specialist | D36: =VLOOKUP(A36,$A$3:$D$12,4) -> 96000 | E36: =VLOOKUP(A36,$A$3:$E$12,5,1) -> 6 | F36: =VLOOKUP(A36,$H$3:$I$12,2) -> 0.03
A37: E102 | B37: =VLOOKUP(A37,$A$3:$E$12,2,2) -> Priya Mukherjee | C37: =VLOOKUP(A37,$A$3:$C$12,3) -> Assistant Manager | D37: =VLOOKUP(A37,$A$3:$D$12,4) -> 100000 | E37: =VLOOKUP(A37,$A$3:$E$12,5,1) -> 2 | F37: =VLOOKUP(A37,$H$3:$I$12,2) -> 0.03
A38: E110 | B38: =VLOOKUP(A38,$A$3:$E$12,2,2) -> Anjali Deshpande | C38: =VLOOKUP(A38,$A$3:$C$12,3) -> Software Developer | D38: =VLOOKUP(A38,$A$3:$D$12,4) -> 110000 | E38: =VLOOKUP(A38,$A$3:$E$12,5,1) -> 9 | F38: =VLOOKUP(A38,$H$3:$I$12,2) -> 0.05
A39: E101 | B39: =VLOOKUP(A39,$A$3:$E$12,2,2) -> Arjun Sharma | C39: =VLOOKUP(A39,$A$3:$C$12,3) -> Manager | D39: =VLOOKUP(A39,$A$3:$D$12,4) -> 120000 | E39: =VLOOKUP(A39,$A$3:$E$12,5,1) -> 15 | F39: =VLOOKUP(A39,$H$3:$I$12,2) -> 0.05

Sheet Age wise Analysis
A1: First Name | B1: Last name | C1: Full Name | D1: Department | E1: Grade | F1: Total_Experience | G1: Experience_as_manager | H1: Gender | I1: CTC | J1: Date of Join | K1: DOB | L1: Today | M1: age
A2: Vijay | B2: Mahajan | C2: =_xlfn.CONCAT(A2," ",B2) -> Vijay Mahajan | D2: Operations | E2: G2 | F2: 40 | G2: 6 | H2: Male | I2: 231545 | J2: 38033 | K2: 26976 | L2: =TODAY() -> 45980 | M2: =YEARFRAC(K2,L2) -> 52.030556
A3: Suresh | B3: Desai | C3: =_xlfn.CONCAT(A3," ",B3) -> Suresh Desai | D3: Operations | E3: G2 | F3: 50 | G3: 14 | H3: Male | I3: 175000 | J3: 39122 | K3: 28006 | L3: =TODAY() -> 45980 | M3: =YEARFRAC(K3,L3) -> 49.211111
A4: Priya | B4: Patel | C4: =_xlfn.CONCAT(A4," ",B4) -> Priya Patel | D4: Operations | E4: G2 | F4: 34 | G4: 2 | H4: Male | I4: 173200 | J4: 37527 | K4: 26113 | L4: =TODAY() -> 45980 | M4: =YEARFRAC(K4,L4) -> 54.388889
A5: Nisha | B5: Dey | C5: =_xlfn.CONCAT(A5," ",B5) -> Nisha Dey | D5: Operations | E5: G2 | F5: 24 | G5: 0 | H5: Male | I5: 155750 | J5: 43038 | K5: 27765 | L5: =TODAY() -> 45980 | M5: =YEARFRAC(K5,L5) -> 49.869444
A6: Arun | B6: Parekh | C6: =_xlfn.CONCAT(A6," ",B6) -> Arun Parekh | D6: Operations | E6: G2 | F6: 34 | G6: 0 | H6: Female | I6: 151768 | J6: 39714 | K6: 28356 | L6: =TODAY() -> 45980 | M6: =YEARFRAC(K6,L6) -> 48.25
A7: Kavita | B7: Joshi | C7: =_xlfn.CONCAT(A7," ",B7) -> Kavita Joshi | D7: Operations | E7: G2 | F7: 27 | G7: 0 | H7: Male | I7: 147765 | J7: 39571 | K7: 28170 | L7: =TODAY() -> 45980 | M7: =YEARFRAC(K7,L7) -> 48.763889
A8: Rupali | B8: Mukherjee | C8: =_xlfn.CONCAT(A8," ",B8) -> Rupali Mukherjee | D8: Operations | E8: G2 | F8: 24 | G8: 0 | H8: Male | I8: 146500 | J8: 44278 | K8: 25919 | L8: =TODAY() -> 45980 | M8: =YEARFRAC(K8,L8) -> 54.922222
A9: Rajesh | B9: Gupta | C9: =_xlfn.CONCAT(A9," ",B9) -> Rajesh Gupta | D9: Operations | E9: G2 | F9: 53 | G9: 14 | H9: Male | I9: 141500 | J9: 38464 | K9: 27354 | L9: =TODAY() -> 45980 | M9: =YEARFRAC(K9,L9) -> 50.994444
A10: Sheetal | B10: Dhawan | C10: =_xlfn.CONCAT(A10," ",B10) -> Sheetal Dhawan | D10: Operations | E10: G2 | F10: 49 | G10: 12 | H10: Female | I10: 140096 | J10: 39932 | K10: 28497 | L10: =TODAY() -> 45980 | M10: =YEARFRAC(K10,L10) -> 47.866667
A11: Aarav | B11: Sharma | C11: =_xlfn.CONCAT(A11," ",B11) -> Aarav Sharma | D11: Operations | E11: G2 | F11: 24 | G11: 0 | H11: Male | I11: 139750 | J11: 37057 | K11: 25639 | L11: =TODAY() -> 45980 | M11: =YEARFRAC(K11,L11) -> 55.686111
A12: Rekha | B12: Kapoor | C12: =_xlfn.CONCAT(A12," ",B12) -> Rekha Kapoor | D12: Operations | E12: G1 | F12: 31 | G12: 0 | H12: Female | I12: 137000 | J12: 44136 | K12: 28879 | L12: =TODAY() -> 45980 | M12: =YEARFRAC(K12,L12) -> 46.819444
A13: Suman | B13: Bansal | C13: =_xlfn.CONCAT(A13," ",B13) -> Suman Bansal | D13: Operations | E13: G1 | F13: 45 | G13: 15 | H13: Male | I13: 134885 | J13: 39177 | K13: 28118 | L13: =TODAY() -> 45980 | M13: =YEARFRAC(K13,L13) -> 48.902778
... A51: Rajendra | B51: Sood | C51: =_xlfn.CONCAT(A51," ",B51) -> Rajendra Sood | D51: Marketing | E51: G2 | F51: 33 | G51: 0 | H51: Male | I51: 70768 | J51: 40494 | K51: 28939 | L51: =TODAY() -> 45980 | M51: =YEARFRAC(K51,L51) -> 46.65
C52: =_xlfn.CONCAT(A52," ",B52)

Sheet Assignments Questions
A1: Assignment Questions
A2: For Age wise Analysis
A3: 1. Find out age of the all the people.
A4: 2. Complete the Full name column
A5: 3. Do the Analysis using FIlter and Sort and come up with the insights (4 atleast)
A6: 4. You can use conditional formating and find out 2 insights
