Workbook

Sheet Quick Insights 1
A1: Sample Super Store Dataset
A2: Order Date | B2: Country | C2: Region | D2: Market | E2: Product ID | F2: Category | G2: Sub-Category | H2: Product Name | I2: Sales | J2: Quantity | K2: Discount | L2: Profit | M2: Shipping Cost | N2: Order Priority
A3: 41954 | B3: United States | C3: Central US | D3: USCA | E3: TEC-PH-5816 | F3: Technology1 | G3: Phones | H3: Samsung Convoy 3 | I3: 221.98 | J3: 2 | K3: 0 | L3: 62.15 | M3: 40.77 | N3: High
A4: 41675 | B4: Australia | C4: Oceania | D4: Asia Pacific | E4: FUR-CH-5379 | F4: Furniture | G4: Chairs | H4: Novimex Executive Leather Armchair, Black | I4: 3709.4 | J4: 9 | K4: 0.1 | L4: 288.77 | M4: 923.63 | N4: Critical
A5: 41929 | B5: Australia | C5: Oceania | D5: Asia Pacific | E5: TEC-PH-5356 | F5: Technology1 | G5: Phones | H5: Nokia Smart Phone, with Caller ID | I5: 5175.17 | J5: 9 | K5: 0.1 | L5: 919.97 | M5: 915.49 | N5: Medium
A6: 41667 | B6: Germany | C6: Western Europe | D6: Europe | E6: TEC-PH-5267 | F6: Technology1 | G6: Phones | H6: Motorola Smart Phone, Cordless | I6: 2892.51 | J6: 5 | K6: 0.1 | L6: -96.54 | M6: 910.16 | N6: Medium
A7: 41948 | B7: Senegal | C7: Western Africa | D7: Africa | E7: TEC-CO-6011 | F7: Technology1 | G7: Copiers | H7: Sharp Wireless Fax, High-Speed | I7: 2832.96 | J7: 8 | K7: 0 | L7: 311.52 | M7: 903.04 | N7: Critical
A8: 41818 | B8: Australia | C8: Oceania | D8: Asia Pacific | E8: TEC-PH-5842 | F8: Technology1 | G8: Phones | H8: Samsung Smart Phone, with Caller ID | I8: 2862.68 | J8: 5 | K8: 0.1 | L8: 763.28 | M8: 897.35 | N8: Critical
A9: 41219 | B9: New Zealand | C9: Oceania | D9: Asia Pacific | E9: FUR-CH-5378 | F9: Furniture | G9: Chairs | H9: Novimex Executive Leather Armchair, Adjustable | I9: 1822.08 | J9: 4 | K9: 0 | L9: 564.84 | M9: 894.77 | N9: Critical
A10: 41378 | B10: New Zealand | C10: Oceania | D10: Asia Pacific | E10: FUR-TA-3764 | F10: Furniture | G10: Tables | H10: Chromcraft Conference Table, Fully Assembled | I10: 5244.84 | J10: 6 | K10: 0 | L10: 996.48 | M10: 878.38 | N10: High
A11: 41954 | B11: United States | C11: Central US | D11: USCA | E11: FUR-BO-5957 | F11: Furniture | G11: Bookcases | H11: Sauder Facets Collection Library, Sky Alder Finish | I11: 341.96 | J11: 2 | K11: 0 | L11: 54.71 | M11: 25.27 | N11: High
A12: 40974 | B12: United States | C12: Western US | D12: USCA | E12: FUR-CH-4421 | F12: Furniture | G12: Chairs | H12: Global Push Button Manager's Chair, Indigo | I12: 48.71 | J12: 1 | K12: 0.2 | L12: 5.48 | M12: 11.13 | N12: High
A13: 40974 | B13: United States | C13: Western US | D13: USCA | E13: OFF-AR-5309 | F13: Office Supplies | G13: Art | H13: Newell 330 | I13: 17.94 | J13: 3 | K13: 0 | L13: 4.66 | M13: 4.29 | N13: High
A14: 41383 | B14: Afghanistan | C14: Southern Asia | D14: Asia Pacific | E14: FUR-TA-3420 | F14: Furniture | G14: Tables | H14: Bevis Conference Table, Fully Assembled | I14: 4626.15 | J14: 5 | K14: 0 | L14: 647.55 | M14: 835.57 | N14: High
... A21: 42035 | B21: Australia | C21: Oceania | D21: Asia Pacific | E21: TEC-CO-3597 | F21: Technology1 | G21: Copiers | H21: Brother Fax Machine, High-Speed | I21: 2565.59 | J21: 9 | K21: 0.1 | L21: 28.4 | M21: 766.93 | N21: Critical
L22: =SUM(L3:L21) -> 11524.28

Sheet Formating + Quick Insights 2
A1: First Name | B1: Last name | C1: initials | D1: Department | E1: Grade | F1: Total_Experience | G1: Experience_as_manager | H1: Gender | I1: CTC | J1: Date of Join | K1: DOB | L1: today | M1: Age | N1: Age
A2: Aarav | B2: Sharma | C2: =PROPER(A2) -> Aarav | D2: Operations | E2: G2 | F2: 24 | G2: 0 | H2: Male | I2: 139750 | J2: 37057 | K2: 25639 | L2: =TODAY() -> 45980 | M2: =(L2-K2)/365 -> 55.728767 | N2: =DATEDIF(K2,TODAY(),"y") -> 55
A3: Nisha | B3: Dey | C3: =PROPER(A3) -> Nisha | D3: Operations | E3: G2 | F3: 24 | G3: 0 | H3: Male | I3: 155750 | J3: 43038 | K3: 27765 | L3: =TODAY() -> 45980 | M3: =(L3-K3)/365 -> 49.90411 | N3: =DATEDIF(K3,TODAY(),"y") -> 49
A4: Rupali | B4: Mukherjee | C4: =PROPER(A4) -> Rupali | D4: Operations | E4: G2 | F4: 24 | G4: 0 | H4: Male | I4: 146500 | J4: 44278 | K4: 25919 | L4: =TODAY() -> 45980 | M4: =(L4-K4)/365 -> 54.961644 | N4: =DATEDIF(K4,TODAY(),"y") -> 54
A5: Geeta | B5: Chauhan | C5: =PROPER(A5) -> Geeta | D5: Operations | E5: G2 | F5: 25 | G5: 0 | H5: Male | I5: 125196 | J5: 43568 | K5: 28745 | L5: =TODAY() -> 45980 | M5: =(L5-K5)/365 -> 47.219178 | N5: =DATEDIF(K5,TODAY(),"y") -> 47
A6: Usha | B6: Roy | C6: =PROPER(A6) -> Usha | D6: Operations | E6: G2 | F6: 25 | G6: 0 | H6: Male | I6: 94384 | J6: 38635 | K6: 27176 | L6: =TODAY() -> 45980 | M6: =(L6-K6)/365 -> 51.517808 | N6: =DATEDIF(K6,TODAY(),"y") -> 51
A7: Vivek | B7: Rai | C7: =PROPER(A7) -> Vivek | D7: Operations | E7: G1 | F7: 26 | G7: 0 | H7: Male | I7: 93904 | J7: 37914 | K7: 26463 | L7: =TODAY() -> 45980 | M7: =(L7-K7)/365 -> 53.471233 | N7: =DATEDIF(K7,TODAY(),"y") -> 53
A8: Kavita | B8: Joshi | C8: =PROPER(A8) -> Kavita | D8: Operations | E8: G2 | F8: 27 | G8: 0 | H8: Male | I8: 147765 | J8: 39571 | K8: 28170 | L8: =TODAY() -> 45980 | M8: =(L8-K8)/365 -> 48.794521 | N8: =DATEDIF(K8,TODAY(),"y") -> 48
A9: Radha | B9: Goyal | C9: =PROPER(A9) -> Radha | D9: Operations | E9: G2 | F9: 29 | G9: 0 | H9: Male | I9: 132261 | J9: 40582 | K9: 25802 | L9: =TODAY() -> 45980 | M9: =(L9-K9)/365 -> 55.282192 | N9: =DATEDIF(K9,TODAY(),"y") -> 55
A10: Rekha | B10: Kapoor | C10: =PROPER(A10) -> Rekha | D10: Operations | E10: G1 | F10: 31 | G10: 0 | H10: Female | I10: 137000 | J10: 44136 | K10: 28879 | L10: =TODAY() -> 45980 | M10: =(L10-K10)/365 -> 46.852055 | N10: =DATEDIF(K10,TODAY(),"y") -> 46
A11: Anand | B11: Mittal | C11: =PROPER(A11) -> Anand | D11: Marketing | E11: G2 | F11: 31 | G11: 0 | H11: Female | I11: 77000 | J11: 42634 | K11: 27746 | L11: =TODAY() -> 45980 | M11: =(L11-K11)/365 -> 49.956164 | N11: =DATEDIF(K11,TODAY(),"y") -> 49
A12: Ananya | B12: Singh | C12: =PROPER(A12) -> Ananya | D12: Operations | E12: G2 | F12: 32 | G12: 0 | H12: Male | I12: 115000 | J12: 37999 | K12: 26788 | L12: =TODAY() -> 45980 | M12: =(L12-K12)/365 -> 52.580822 | N12: =DATEDIF(K12,TODAY(),"y") -> 52
A13: Nitin | B13: Jain | C13: =PROPER(A13) -> Nitin | D13: Operations | E13: G2 | F13: 32 | G13: 0 | H13: Male | I13: 114778 | J13: 38719 | K13: 27681 | L13: =TODAY() -> 45980 | M13: =(L13-K13)/365 -> 50.134247 | N13: =DATEDIF(K13,TODAY(),"y") -> 50
... A51: Manish | B51: Agarwal | C51: =PROPER(A51) -> Manish | D51: Marketing | E51: G2 | F51: 51 | G51: 13 | H51: Male | I51: 86373 | J51: 43104 | K51: 28300 | L51: =TODAY() -> 45980 | M51: =(L51-K51)/365 -> 48.438356 | N51: =DATEDIF(K51,TODAY(),"y") -> 48

Sheet Insights 3
A1: Year | B1: Month | C1: Purchase Vaolume
A2: 2022 | B2: January | C2: 9350
A3: 2022 | B3: February | C3: 8420
A4: 2022 | B4: March | C4: 10110
A5: 2022 | B5: April | C5: 7890
A6: 2022 | B6: May | C6: 9980
A7: 2022 | B7: June | C7: 11200
A8: 2022 | B8: July | C8: 8540
A9: 2022 | B9: August | C9: 9010
A10: 2022 | B10: September | C10: 10200
A11: 2022 | B11: October | C11: 8730
A12: 2022 | B12: November | C12: 9840
A13: 2022 | B13: December | C13: 10050
... A25: 2023 | B25: December | C25: 9670

Sheet Data Formating
A1: Order Date | B1: Country | C1: Region | D1: Market | E1: Product ID | F1: Category | G1: Sub-Category | H1: Product Name | I1: Sales | J1: Quantity | K1: Discount | L1: Profit | M1: Shipping Cost | N1: Order Priority
A2: 41954 | B2: United States | C2: Central US | D2: USCA | E2: TEC-PH-5816 | F2: Technology | G2: Phones | H2: Samsung Convoy 3 | I2: $221.98 | J2: 2 | K2: 0 | L2: $62.15 | M2: 40.77 | N2: High
A3: 41675 | B3: Australia | C3: Oceania | D3: Asia Pacific | E3: FUR-CH-5379 | F3: Furniture | G3: Chairs | H3: Novimex Executive Leather Armchair, Black | I3: $3,709.40 | J3: 9 | K3: 0.1 | L3: -$288.77 | M3: 923.63 | N3: Critical
A4: 41929 | B4: Australia | C4: Oceania | D4: Asia Pacific | E4: TEC-PH-5356 | F4: Technology | G4: Phones | H4: Nokia Smart Phone, with Caller ID | I4: $5,175.17 | J4: 9 | K4: 0.1 | L4: $919.97 | M4: 915.49 | N4: Medium
A5: 41667 | B5: Germany | C5: Western Europe | D5: Europe | E5: TEC-PH-5267 | F5: Technology | G5: Phones | H5: Motorola Smart Phone, Cordless | I5: $2,892.51 | J5: 5 | K5: 0.1 | L5: -$96.54 | M5: 910.16 | N5: Medium
A6: 41948 | B6: Senegal | C6: Western Africa | D6: Africa | E6: TEC-CO-6011 | F6: Technology | G6: Copiers | H6: Sharp Wireless Fax, High-Speed | I6: $2,832.96 | J6: 8 | K6: 0 | L6: $311.52 | M6: 903.04 | N6: Critical
A7: 41818 | B7: Australia | C7: Oceania | D7: Asia Pacific | E7: TEC-PH-5842 | F7: Technology | G7: Phones | H7: Samsung Smart Phone, with Caller ID | I7: $2,862.68 | J7: 5 | K7: 0.1 | L7: $763.28 | M7: 897.35 | N7: Critical
A8: 41219 | B8: New Zealand | C8: Oceania | D8: Asia Pacific | E8: FUR-CH-5378 | F8: Furniture | G8: Chairs | H8: Novimex Executive Leather Armchair, Adjustable | I8: $1,822.08 | J8: 4 | K8: 0 | L8: $564.84 | M8: 894.77 | N8: Critical
A9: 41378 | B9: New Zealand | C9: Oceania | D9: Asia Pacific | E9: FUR-TA-3764 | F9: Furniture | G9: Tables | H9: Chromcraft Conference Table, Fully Assembled | I9: $5,244.84 | J9: 6 | K9: 0 | L9: $996.48 | M9: 878.38 | N9: High
A10: 41954 | B10: United States | C10: Central US | D10: USCA | E10: FUR-BO-5957 | F10: Furniture | G10: Bookcases | H10: Sauder Facets Collection Library, Sky Alder Finish | I10: $341.96 | J10: 2 | K10: 0 | L10: $54.71 | M10: 25.27 | N10: High
A11: 40974 | B11: United States | C11: Western US | D11: USCA | E11: FUR-CH-4421 | F11: Furniture | G11: Chairs | H11: Global Push Button Manager's Chair, Indigo | I11: $48.71 | J11: 1 | K11: 0.2 | L11: $5.48 | M11: 11.13 | N11: High
A12: 40974 | B12: United States | C12: Western US | D12: USCA | E12: OFF-AR-5309 | F12: Office Supplies | G12: Art | H12: Newell 330 | I12: $17.94 | J12: 3 | K12: 0 | L12: $4.66 | M12: 4.29 | N12: High
A13: 41383 | B13: Afghanistan | C13: Southern Asia | D13: Asia Pacific | E13: FUR-TA-3420 | F13: Furniture | G13: Tables | H13: Bevis Conference Table, Fully Assembled | I13: $4,626.15 | J13: 5 | K13: 0 | L13: $647.55 | M13: 835.57 | N13: High
... A20: 42035 | B20: Australia | C20: Oceania | D20: Asia Pacific | E20: TEC-CO-3597 | F20: Technology | G20: Copiers | H20: Brother Fax Machine, High-Speed | I20: $2,565.59 | J20: 9 | K20: 0.1 | L20: $28.40 | M20: 766.93 | N20: Critical

Sheet Basic Formulas
A1: Order Date | B1: Country | C1: Region | D1: Market | E1: Product ID | F1: Category | G1: Sub-Category | H1: Product Name | I1: Sales | J1: Quantity
A2: 41954 | B2: United States | C2: Central US | D2: USCA | E2: TEC-PH-5816 | F2: Technology | G2: Phones | H2: Samsung Convoy 3 | I2: 221.98 | J2: 2
A3: 41675 | B3: Australia | C3: Oceania | D3: Asia Pacific | E3: FUR-CH-5379 | F3: Furniture | G3: Chairs | H3: Novimex Executive Leather Armchair, Black | I3: 3709.4 | J3: 9
A4: 41929 | B4: Australia | C4: Oceania | D4: Asia Pacific | E4: TEC-PH-5356 | F4: Technology | G4: Phones | H4: Nokia Smart Phone, with Caller ID | I4: 5175.17 | J4: 9
A5: 41667 | B5: Germany | C5: Western Europe | D5: Europe | E5: TEC-PH-5267 | F5: Technology | G5: Phones | H5: Motorola Smart Phone, Cordless | I5: 2892.51 | J5: 5
A6: 41948 | B6: Senegal | C6: Western Africa | D6: Africa | E6: TEC-CO-6011 | F6: Technology | G6: Copiers | H6: Sharp Wireless Fax, High-Speed | I6: 2832.96 | J6: 8
A7: 41818 | B7: Australia | C7: Oceania | D7: Asia Pacific | E7: TEC-PH-5842 | F7: Technology | G7: Phones | H7: Samsung Smart Phone, with Caller ID | I7: 2862.68 | J7: 5
A8: 41219 | B8: New Zealand | C8: Oceania | D8: Asia Pacific | E8: FUR-CH-5378 | F8: Furniture | G8: Chairs | H8: Novimex Executive Leather Armchair, Adjustable | I8: 1822.08 | J8: 4
A9: 41378 | B9: New Zealand | C9: Oceania | D9: Asia Pacific | E9: FUR-TA-3764 | F9: Furniture | G9: Tables | H9: Chromcraft Conference Table, Fully Assembled | I9: 5244.84 | J9: 6
A10: 41954 | B10: United States | C10: Central US | D10: USCA | E10: FUR-BO-5957 | F10: Furniture | G10: Bookcases | H10: Sauder Facets Collection Library, Sky Alder Finish | I10: 341.96 | J10: 2
A11: 40974 | B11: United States | C11: Western US | D11: USCA | E11: FUR-CH-4421 | F11: Furniture | G11: Chairs | H11: Global Push Button Manager's Chair, Indigo | I11: 48.71 | J11: 1
A12: 40974 | B12: United States | C12: Western US | D12: USCA | E12: OFF-AR-5309 | F12: Office Supplies | G12: Art | H12: Newell 330 | I12: 17.94 | J12: 3
A13: 41383 | B13: Afghanistan | C13: Southern Asia | D13: Asia Pacific | E13: FUR-TA-3420 | F13: Furniture | G13: Tables | H13: Bevis Conference Table, Fully Assembled | I13: 4626.15 | J13: 5
... A20: 42035 | B20: Australia | C20: Oceania | D20: Asia Pacific | E20: TEC-CO-3597 | F20: Technology | G20: Copiers | H20: Brother Fax Machine, High-Speed | I20: 2565.59 | J20: 9

Sheet Sheet4
A1: Average Function
A2: Sales Person | B2: Jan | C2: Feb | D2: March | E2: Total | F2: Average
A3: amit | B3: 1435 | C3: 1592 | D3: 2335 | E3: =SUM(B3:D3) -> 5362 | F3: =AVERAGE(B3:D3) -> 1787.3333
A4: suman | B4: 1854 | C4: 1635 | D4: 2232 | E4: =SUM(B4:D4) -> 5721 | F4: =AVERAGE(B4:D4) -> 1907
A5: arti | B5: 1524 | C5: 2879 | D5: 1739 | E5: =SUM(B5:D5) -> 6142 | F5: =AVERAGE(B5:D5) -> 2047.3333
A6: karan | B6: 2716 | C6: 1456 | D6: 2220 | E6: =SUM(B6:D6) -> 6392 | F6: =AVERAGE(B6:D6) -> 2130.6667
A7: rohit | B7: 2117 | C7: 1665 | D7: 2371 | E7: =SUM(B7:D7) -> 6153 | F7: =AVERAGE(B7:D7) -> 2051
A8: raman | B8: 1191 | C8: 2515 | D8: 1098 | E8: =SUM(B8:D8) -> 4804 | F8: =AVERAGE(B8:D8) -> 1601.3333
A9: rinki | B9: 2713 | C9: 1929 | D9: 1257 | E9: =SUM(B9:D9) -> 5899 | F9: =AVERAGE(B9:D9) -> 1966.3333
A11: AverageA Function
A12: Sales Person | B12: Jan | C12: Feb | D12: March | E12: Total | F12: Average
A13: amit | B13: 1435 | C13: 1592 | D13: 2335 | F13: =AVERAGEA(B13:D13) -> 1787.3333
A14: suman | B14: 1854 | C14: 1635 | D14: 2232 | F14: =AVERAGEA(B14:D14) -> 1907
A15: arti | B15: 1524 | C15: leave | D15: Leave | F15: =AVERAGEA(B15:D15) -> 508
A16: karan | B16: 2716 | C16: 1456 | D16: 2220 | F16: =AVERAGEA(B16:D16) -> 2130.6667
A17: rohit | B17: 2117 | C17: 1665 | D17: 2371 | F17: =AVERAGEA(B17:D17) -> 2051
A18: raman | B18: 1191 | C18: 2515 | D18: 1098 | F18: =AVERAGEA(B18:D18) -> 1601.3333
A19: rinki | B19: 2713 | C19: 1929 | D19: 1257 | F19: =AVERAGEA(B19:D19) -> 1966.3333
A21: Average IFS
A22: Sales Rep | B22: Units | C22: Sales | G22: Data Consolidation
A23: Aniket | B23: 130 | C23: 13084
A24: Aman | B24: 205 | C24: 20582 | G24: Sales Rep | H24: Avg.Sales
A25: Aniket | B25: 480 | C25: 48001 | G25: Aniket | H25: =AVERAGEIFS($C$23:$C$36,$A$23:$A$36,G25) -> 34589.8
A26: Arti | B26: 405 | C26: 40594 | G26: Arti | H26: =AVERAGEIFS($C$23:$C$36,$A$23:$A$36,G26) -> 22268
A27: Amresh | B27: 421 | C27: 42154 | G27: Amresh | H27: =AVERAGEIFS($C$23:$C$36,$A$23:$A$36,G27) -> 42154
A28: Arti | B28: 54 | C28: 5460 | G28: Aman | H28: =AVERAGEIFS($C$23:$C$36,$A$23:$A$36,G28) -> 34776
A29: Aniket | B29: 379 | C29: 37976 | G29: Mayur | H29: =AVERAGEIFS($C$23:$C$36,$A$23:$A$36,G29) -> 40202
A30: Aniket | B30: 390 | C30: 39011
A31: Aman | B31: 408 | C31: 40840
A32: Mayur | B32: 402 | C32: 40202
A33: Arti | B33: 207 | C33: 20750
A34: Aniket | B34: 348 | C34: 34877
A35: Aman | B35: 429 | C35: 42906
A36: Anita | B36: 343 | C36: 34359
A38: Average IFS
A39: Date | B39: Product | C39: Store | D39: Sales
A40: 41001 | B40: Juice | C40: Store 2 | D40: 392
A41: 41000 | B41: Wine | C41: Store 1 | D41: 162
A42: 41003 | B42: Juice | C42: Store 2 | D42: 540 | I42: Data Consolidation
A43: 41005 | B43: Juice | C43: Store 3 | D43: 75
...
